Workbook

Sheet Apr
A2: CB2025-2026.xlsx | C2: Anurag-Professional | D2: Status: | E2: Individual | G2: CASHBOOK | I2: PAN: | J2: AFIPG7802B | L2: Asst.Yr. | N2: Month | O2: =CHOOSE(MONTH(A6),"Jan","Feb","Mar","Apr","May","Jun","Jul","Aug","Sep","Oct","Nov","Dec") -> Apr
A4: Date | B4: Reciept A/c | C4: Reciept Particulars | D4: L.F. No. | E4: VNH | F4: Cash | G4: Cash | H4: Chq. | I4: Total | J4: Date | K4: Payment A/c | L4: Payment Particulars | M4: L.F. No. | N4: Cash | O4: Chq. | P4: Total | Q4: Balance
A6: 45383 | B6: Balance | C6: B/F | F6: 99619 | G6: =SUM(E6:F6) -> 99619 | I6: =I5+G6 -> 99619 | J6: 45383 | P6: =P5+N6 -> 0 | Q6: =I6-P6 -> 99619
A7: 45384 | G7: =SUM(E7:F7) -> 0 | I7: =I6+G7 -> 99619 | J7: 45384 | P7: =P6+N7 -> 0 | Q7: =I7-P7 -> 99619
A8: 45385 | G8: =SUM(E8:F8) -> 0 | I8: =I7+G8 -> 99619 | J8: 45385 | K8: Salary | L8: Neeraj | M8: 9 | N8: 3000 | P8: =P7+N8 -> 3000 | Q8: =I8-P8 -> 96619
A9: 45386 | G9: =SUM(E9:F9) -> 0 | I9: =I8+G9 -> 99619 | J9: 45386 | K9: Misc. | L9: Stationery | M9: 6 | N9: 280 | P9: =P8+N9 -> 3280 | Q9: =I9-P9 -> 96339
A10: 45387 | G10: =SUM(E10:F10) -> 0 | I10: =I9+G10 -> 99619 | J10: 45387 | P10: =P9+N10 -> 3280 | Q10: =I10-P10 -> 96339
A11: 45388 | G11: =SUM(E11:F11) -> 0 | I11: =I10+G11 -> 99619 | J11: 45388 | P11: =P10+N11 -> 3280 | Q11: =I11-P11 -> 96339
A12: 45389 | G12: =SUM(E12:F12) -> 0 | I12: =I11+G12 -> 99619 | J12: 45389 | P12: =P11+N12 -> 3280 | Q12: =I12-P12 -> 96339
A13: 45390 | G13: =SUM(E13:F13) -> 0 | I13: =I12+G13 -> 99619 | J13: 45390 | P13: =P12+N13 -> 3280 | Q13: =I13-P13 -> 96339
A14: 45391 | G14: =SUM(E14:F14) -> 0 | I14: =I13+G14 -> 99619 | J14: 45391 | K14: ICICI | L14: NFS/CASH WDL/410015026840/S1ACAG49/AGRA /09-04-241558 | N14: 10000 | P14: =P13+N14 -> 13280 | Q14: =I14-P14 -> 86339
A15: 45392 | B15: Patients | C15: UPI/410117325925/fee/akjain62@unionb/Union Bank of I/UOBD2EB54F43C8E4A92A1ACB3AFBF6ED855 | G15: =SUM(E15:F15) -> 0 | H15: 300 | I15: =I14+G15 -> 99619 | J15: 45392 | K15: ICICI | L15: UPI/410117325925/fee/akjain62@unionb/Union Bank of I/UOBD2EB54F43C8E4A92A1ACB3AFBF6ED855 | O15: 300 | P15: =P14+N15 -> 13280 | Q15: =I15-P15 -> 86339
A16: 45393 | G16: =SUM(E16:F16) -> 0 | I16: =I15+G16 -> 99619 | J16: 45393 | P16: =P15+N16 -> 13280 | Q16: =I16-P16 -> 86339
A17: 45394 | G17: =SUM(E17:F17) -> 0 | I17: =I16+G17 -> 99619 | J17: 45394 | P17: =P16+N17 -> 13280 | Q17: =I17-P17 -> 86339
A18: 45395 | G18: =SUM(E18:F18) -> 0 | I18: =I17+G18 -> 99619 | J18: 45395 | P18: =P17+N18 -> 13280 | Q18: =I18-P18 -> 86339
A19: 45396 | G19: =SUM(E19:F19) -> 0 | I19: =I18+G19 -> 99619 | J19: 45396 | P19: =P18+N19 -> 13280 | Q19: =I19-P19 -> 86339
A20: 45397 | G20: =SUM(E20:F20) -> 0 | I20: =I19+G20 -> 99619 | J20: 45397 | K20: Veh. Exp. | L20: Petrol | M20: 11 | N20: 500 | P20: =P19+N20 -> 13780 | Q20: =I20-P20 -> 85839
A21: 45398 | G21: =SUM(E21:F21) -> 0 | I21: =I20+G21 -> 99619 | J21: 45398 | P21: =P20+N21 -> 13780 | Q21: =I21-P21 -> 85839
A22: 45399 | G22: =SUM(E22:F22) -> 0 | I22: =I21+G22 -> 99619 | J22: 45399 | P22: =P21+N22 -> 13780 | Q22: =I22-P22 -> 85839
A23: 45400 | G23: =SUM(E23:F23) -> 0 | I23: =I22+G23 -> 99619 | J23: 45400 | P23: =P22+N23 -> 13780 | Q23: =I23-P23 -> 85839
A24: 45401 | G24: =SUM(E24:F24) -> 0 | I24: =I23+G24 -> 99619 | J24: 45401 | P24: =P23+N24 -> 13780 | Q24: =I24-P24 -> 85839
A25: 45402 | G25: =SUM(E25:F25) -> 0 | I25: =I24+G25 -> 99619 | J25: 45402 | P25: =P24+N25 -> 13780 | Q25: =I25-P25 -> 85839
A26: 45403 | G26: =SUM(E26:F26) -> 0 | I26: =I25+G26 -> 99619 | J26: 45403 | K26: Salary | L26: Gaurav | M26: 9 | N26: 3000 | P26: =P25+N26 -> 16780 | Q26: =I26-P26 -> 82839
A27: 45404 | D27: 8 | G27: =SUM(E27:F27) -> 0 | H27: 300 | I27: =I26+G27 -> 99619 | J27: 45404 | K27: ICICI | L27: UPI/311273166081/UPI/7409404440.wa.y/Kotak Mahindra /AXISWC3C4DB46691D4D54E08E7 | M27: 4 | O27: 300 | P27: =P26+N27 -> 16780 | Q27: =I27-P27 -> 82839
A28: 45405 | G28: =SUM(E28:F28) -> 0 | I28: =I27+G28 -> 99619 | J28: 45405 | P28: =P27+N28 -> 16780 | Q28: =I28-P28 -> 82839
A29: 45406 | G29: =SUM(E29:F29) -> 0 | I29: =I28+G29 -> 99619 | J29: 45406 | P29: =P28+N29 -> 16780 | Q29: =I29-P29 -> 82839
A30: 45407 | G30: =SUM(E30:F30) -> 0 | I30: =I29+G30 -> 99619 | J30: 45407 | P30: =P29+N30 -> 16780 | Q30: =I30-P30 -> 82839
A31: 45408 | G31: =SUM(E31:F31) -> 0 | I31: =I30+G31 -> 99619 | J31: 45408 | P31: =P30+N31 -> 16780 | Q31: =I31-P31 -> 82839
A32: 45409 | G32: =SUM(E32:F32) -> 0 | I32: =I31+G32 -> 99619 | J32: 45409 | P32: =P31+N32 -> 16780 | Q32: =I32-P32 -> 82839
A33: 45410 | G33: =SUM(E33:F33) -> 0 | I33: =I32+G33 -> 99619 | J33: 45410 | P33: =P32+N33 -> 16780 | Q33: =I33-P33 -> 82839
A34: 45411 | G34: =SUM(E34:F34) -> 0 | I34: =I33+G34 -> 99619 | J34: 45411 | P34: =P33+N34 -> 16780 | Q34: =I34-P34 -> 82839
A35: 45412 | G35: =SUM(E35:F35) -> 0 | I35: =I34+G35 -> 99619 | J35: 45412 | K35: Balance | L35: C/F | N35: =Q34 -> 82839 | P35: =P34+N35 -> 99619 | Q35: =I35-P35 -> 0
H37: =SUM(H6:H35) -> 600 | O37: =SUM(O6:O35) -> 600

Sheet May
A2: CB2025-2026.xlsx | C2: Anurag-Professional | D2: Status: | E2: Individual | G2: CASHBOOK | I2: PAN: | J2: AFIPG7802B | L2: Asst.Yr. | N2: Month | O2: =CHOOSE(MONTH(A6),"Jan","Feb","Mar","Apr","May","Jun","Jul","Aug","Sep","Oct","Nov","Dec") -> May
A4: Date | B4: Reciept A/c | C4: Reciept Particulars | D4: L.F. No. | E4: VNH | F4: Cash | G4: Cash | H4: Chq. | I4: Total | J4: Date | K4: Payment A/c | L4: Payment Particulars | M4: L.F. No. | N4: Cash | O4: Chq. | P4: Total | Q4: Balance
A6: 45413 | B6: Balance | C6: B/F | F6: =Apr!N35 -> 82839 | G6: =Apr!N35 -> 82839 | I6: =I5+G6 -> 82839 | J6: 45413 | P6: =P5+N6 -> 0 | Q6: =I6-P6 -> 82839
A7: 45414 | G7: =SUM(E7:F7) -> 0 | I7: =I6+G7 -> 82839 | J7: 45414 | P7: =P6+N7 -> 0 | Q7: =I7-P7 -> 82839
A8: 45415 | B8: ICICI | C8: NFS/S1ACAG49/CASH WDL/03-05-23 | D8: 4 | F8: 10000 | G8: =SUM(E8:F8) -> 10000 | I8: =I7+G8 -> 92839 | J8: 45415 | P8: =P7+N8 -> 0 | Q8: =I8-P8 -> 92839
A9: 45416 | G9: =SUM(E9:F9) -> 0 | I9: =I8+G9 -> 92839 | J9: 45416 | P9: =P8+N9 -> 0 | Q9: =I9-P9 -> 92839
A10: 45417 | G10: =SUM(E10:F10) -> 0 | I10: =I9+G10 -> 92839 | J10: 45417 | P10: =P9+N10 -> 0 | Q10: =I10-P10 -> 92839
A11: 45418 | G11: =SUM(E11:F11) -> 0 | I11: =I10+G11 -> 92839 | J11: 45418 | P11: =P10+N11 -> 0 | Q11: =I11-P11 -> 92839
A12: 45419 | G12: =SUM(E12:F12) -> 0 | I12: =I11+G12 -> 92839 | J12: 45419 | K12: Salary | L12: Neeraj | M12: 9 | N12: 3000 | P12: =P11+N12 -> 3000 | Q12: =I12-P12 -> 89839
A13: 45420 | G13: =SUM(E13:F13) -> 0 | I13: =I12+G13 -> 92839 | J13: 45420 | P13: =P12+N13 -> 3000 | Q13: =I13-P13 -> 89839
A14: 45421 | G14: =SUM(E14:F14) -> 0 | I14: =I13+G14 -> 92839 | J14: 45421 | P14: =P13+N14 -> 3000 | Q14: =I14-P14 -> 89839
A15: 45422 | G15: =SUM(E15:F15) -> 0 | I15: =I14+G15 -> 92839 | J15: 45422 | P15: =P14+N15 -> 3000 | Q15: =I15-P15 -> 89839
A16: 45423 | G16: =SUM(E16:F16) -> 0 | I16: =I15+G16 -> 92839 | J16: 45423 | P16: =P15+N16 -> 3000 | Q16: =I16-P16 -> 89839
A17: 45424 | G17: =SUM(E17:F17) -> 0 | I17: =I16+G17 -> 92839 | J17: 45424 | P17: =P16+N17 -> 3000 | Q17: =I17-P17 -> 89839
A18: 45425 | G18: =SUM(E18:F18) -> 0 | I18: =I17+G18 -> 92839 | J18: 45425 | P18: =P17+N18 -> 3000 | Q18: =I18-P18 -> 89839
A19: 45426 | G19: =SUM(E19:F19) -> 0 | I19: =I18+G19 -> 92839 | J19: 45426 | K19: Veh. Exp. | L19: Petrol | M19: 11 | N19: 500 | P19: =P18+N19 -> 3500 | Q19: =I19-P19 -> 89339
A20: 45427 | G20: =SUM(E20:F20) -> 0 | I20: =I19+G20 -> 92839 | J20: 45427 | P20: =P19+N20 -> 3500 | Q20: =I20-P20 -> 89339
A21: 45428 | G21: =SUM(E21:F21) -> 0 | I21: =I20+G21 -> 92839 | J21: 45428 | P21: =P20+N21 -> 3500 | Q21: =I21-P21 -> 89339
A22: 45429 | G22: =SUM(E22:F22) -> 0 | I22: =I21+G22 -> 92839 | J22: 45429 | P22: =P21+N22 -> 3500 | Q22: =I22-P22 -> 89339
A23: 45430 | G23: =SUM(E23:F23) -> 0 | I23: =I22+G23 -> 92839 | J23: 45430 | P23: =P22+N23 -> 3500 | Q23: =I23-P23 -> 89339
A24: 45431 | G24: =SUM(E24:F24) -> 0 | I24: =I23+G24 -> 92839 | J24: 45431 | P24: =P23+N24 -> 3500 | Q24: =I24-P24 -> 89339
A25: 45432 | G25: =SUM(E25:F25) -> 0 | I25: =I24+G25 -> 92839 | J25: 45432 | P25: =P24+N25 -> 3500 | Q25: =I25-P25 -> 89339
A26: 45433 | G26: =SUM(E26:F26) -> 0 | I26: =I25+G26 -> 92839 | J26: 45433 | P26: =P25+N26 -> 3500 | Q26: =I26-P26 -> 89339
A27: 45434 | B27: Patients | C27: TRF/MARUTINANDAN HEALTHCARE/004877/ICI/03.05.2024 | G27: =SUM(E27:F27) -> 0 | H27: =2160*1.1 -> 2376 | I27: =I26+G27 -> 92839 | J27: 45434 | K27: ICICI | L27: TRF/MARUTINANDAN HEALTHCARE/004877/ICI/03.05.2024 | M27: 9 | O27: 2160 | P27: =P26+N27 -> 3500 | Q27: =I27-P27 -> 89339
A28: 45434 | B28: Patients | C28: TRF/SHRI MARUTINANDAN/004852/ICI/30.04.2024 | I28: =I27+G28 -> 92839 | K28: TDStoIT | O28: 216 | P28: =P27+N28 -> 3500 | Q28: =I28-P28 -> 89339
A29: 45434 | H29: =4950*1.1 -> 5445 | I29: =I28+G29 -> 92839 | K29: ICICI | L29: TRF/SHRI MARUTINANDAN/004852/ICI/30.04.2024 | O29: 4950 | P29: =P28+N29 -> 3500 | Q29: =I29-P29 -> 89339
A30: 45434 | G30: =SUM(E30:F30) -> 0 | I30: =I29+G30 -> 92839 | J30: 45434 | K30: TDStoIT | O30: 495 | P30: =P29+N30 -> 3500 | Q30: =I30-P30 -> 89339
A31: 45436 | G31: =SUM(E31:F31) -> 0 | I31: =I30+G31 -> 92839 | J31: 45436 | P31: =P30+N31 -> 3500 | Q31: =I31-P31 -> 89339
A32: 45437 | G32: =SUM(E32:F32) -> 0 | I32: =I31+G32 -> 92839 | J32: 45437 | P32: =P31+N32 -> 3500 | Q32: =I32-P32 -> 89339
A33: 45438 | G33: =SUM(E33:F33) -> 0 | I33: =I32+G33 -> 92839 | J33: 45438 | P33: =P32+N33 -> 3500 | Q33: =I33-P33 -> 89339
A34: 45439 | G34: =SUM(E34:F34) -> 0 | I34: =I33+G34 -> 92839 | J34: 45439 | P34: =P33+N34 -> 3500 | Q34: =I34-P34 -> 89339
A35: 45440 | G35: =SUM(E35:F35) -> 0 | I35: =I34+G35 -> 92839 | J35: 45440 | P35: =P34+N35 -> 3500 | Q35: =I35-P35 -> 89339
A36: 45441 | B36: ICICI | C36: NFS/S1ACAG49/CASH WDL/28-05-23 | D36: 4 | F36: 10000 | G36: =SUM(E36:F36) -> 10000 | I36: =I35+G36 -> 102839 | J36: 45441 | P36: =P35+N36 -> 3500 | Q36: =I36-P36 -> 99339
A37: 45442 | G37: =SUM(E37:F37) -> 0 | I37: =I36+G37 -> 102839 | J37: 45442 | K37: Veh. Exp. | L37: Petrol | M37: 11 | N37: 2000 | P37: =P36+N37 -> 5500 | Q37: =I37-P37 -> 97339
A38: 45443 | G38: =SUM(E38:F38) -> 0 | I38: =I37+G38 -> 102839 | J38: 45443 | P38: =P37+N38 -> 5500 | Q38: =I38-P38 -> 97339
A39: 45444 | G39: =SUM(E39:F39) -> 0 | I39: =I38+G39 -> 102839 | J39: 45444 | K39: Balance | L39: C/F | N39: =Q38 -> 97339 | P39: =P38+N39 -> 102839 | Q39: =I39-P39 -> 0
H41: =SUM(H6:H39) -> 7821 | O41: =SUM(O6:O39) -> 7821

Sheet Jun
A2: CB2025-2026.xlsx | C2: Anurag-Professional | D2: Status: | E2: Individual | G2: CASHBOOK | I2: PAN: | J2: AFIPG7802B | L2: Asst.Yr. | N2: Month | O2: =CHOOSE(MONTH(A6),"Jan","Feb","Mar","Apr","May","Jun","Jul","Aug","Sep","Oct","Nov","Dec") -> Jun
A4: Date | B4: Reciept A/c | C4: Reciept Particulars | D4: L.F. No. | E4: VNH | F4: Cash | G4: Cash | H4: Chq. | I4: Total | J4: Date | K4: Payment A/c | L4: Payment Particulars | M4: L.F. No. | N4: Cash | O4: Chq. | P4: Total | Q4: Balance
A6: 45444 | B6: Balance | C6: B/F | F6: =May!N39 -> 97339 | G6: =May!N39 -> 97339 | I6: =I5+G6 -> 97339 | J6: 45444 | P6: =P5+N6 -> 0 | Q6: =I6-P6 -> 97339
A7: 45444 | B7: Patients | C7: CLG/SHRI MARUTI NANDAN/277853/CAB/22.05.2024 | D7: 1 | G7: =SUM(E7:F7) -> 0 | I7: =I6+G7 -> 97339 | J7: 45444 | K7: ICICI | L7: CLG/SHRI MARUTI NANDAN/277853/CAB/22.05.2024 | O7: 6300 | P7: =P6+N7 -> 0 | Q7: =I7-P7 -> 97339
A8: 45444 | G8: =SUM(E8:F8) -> 0 | I8: =I7+G8 -> 97339 | J8: 45444 | K8: TDStoIT | O8: 630 | P8: =P7+N8 -> 0 | Q8: =I8-P8 -> 97339
A9: 45447 | G9: =SUM(E9:F9) -> 0 | I9: =I8+G9 -> 97339 | J9: 45447 | P9: =P8+N9 -> 0 | Q9: =I9-P9 -> 97339
A10: 45448 | G10: =SUM(E10:F10) -> 0 | I10: =I9+G10 -> 97339 | J10: 45448 | P10: =P9+N10 -> 0 | Q10: =I10-P10 -> 97339
A11: 45449 | G11: =SUM(E11:F11) -> 0 | I11: =I10+G11 -> 97339 | J11: 45449 | P11: =P10+N11 -> 0 | Q11: =I11-P11 -> 97339
A12: 45450 | G12: =SUM(E12:F12) -> 0 | I12: =I11+G12 -> 97339 | J12: 45450 | P12: =P11+N12 -> 0 | Q12: =I12-P12 -> 97339
A13: 45451 | G13: =SUM(E13:F13) -> 0 | I13: =I12+G13 -> 97339 | J13: 45451 | P13: =P12+N13 -> 0 | Q13: =I13-P13 -> 97339
A14: 45452 | G14: =SUM(E14:F14) -> 0 | I14: =I13+G14 -> 97339 | J14: 45452 | P14: =P13+N14 -> 0 | Q14: =I14-P14 -> 97339
A15: 45453 | G15: =SUM(E15:F15) -> 0 | I15: =I14+G15 -> 97339 | J15: 45453 | P15: =P14+N15 -> 0 | Q15: =I15-P15 -> 97339
A16: 45454 | G16: =SUM(E16:F16) -> 0 | I16: =I15+G16 -> 97339 | J16: 45454 | P16: =P15+N16 -> 0 | Q16: =I16-P16 -> 97339
A17: 45455 | G17: =SUM(E17:F17) -> 0 | I17: =I16+G17 -> 97339 | J17: 45455 | P17: =P16+N17 -> 0 | Q17: =I17-P17 -> 97339
A18: 45456 | G18: =SUM(E18:F18) -> 0 | I18: =I17+G18 -> 97339 | J18: 45456 | P18: =P17+N18 -> 0 | Q18: =I18-P18 -> 97339
A19: 45457 | G19: =SUM(E19:F19) -> 0 | I19: =I18+G19 -> 97339 | J19: 45457 | P19: =P18+N19 -> 0 | Q19: =I19-P19 -> 97339
A20: 45458 | G20: =SUM(E20:F20) -> 0 | I20: =I19+G20 -> 97339 | J20: 45458 | P20: =P19+N20 -> 0 | Q20: =I20-P20 -> 97339
A21: 45459 | G21: =SUM(E21:F21) -> 0 | I21: =I20+G21 -> 97339 | J21: 45459 | P21: =P20+N21 -> 0 | Q21: =I21-P21 -> 97339
A22: 45460 | G22: =SUM(E22:F22) -> 0 | I22: =I21+G22 -> 97339 | J22: 45460 | K22: Veh. Exp. | L22: Petrol | M22: 11 | N22: 500 | P22: =P21+N22 -> 500 | Q22: =I22-P22 -> 96839
A23: 45461 | G23: =SUM(E23:F23) -> 0 | I23: =I22+G23 -> 97339 | J23: 45461 | P23: =P22+N23 -> 500 | Q23: =I23-P23 -> 96839
A24: 45462 | G24: =SUM(E24:F24) -> 0 | I24: =I23+G24 -> 97339 | J24: 45462 | P24: =P23+N24 -> 500 | Q24: =I24-P24 -> 96839
A25: 45463 | G25: =SUM(E25:F25) -> 0 | I25: =I24+G25 -> 97339 | J25: 45463 | P25: =P24+N25 -> 500 | Q25: =I25-P25 -> 96839
A26: 45464 | G26: =SUM(E26:F26) -> 0 | I26: =I25+G26 -> 97339 | J26: 45464 | P26: =P25+N26 -> 500 | Q26: =I26-P26 -> 96839
A27: 45465 | G27: =SUM(E27:F27) -> 0 | I27: =I26+G27 -> 97339 | J27: 45465 | K27: Salary | L27: Gaurav | M27: 9 | N27: 3000 | P27: =P26+N27 -> 3500 | Q27: =I27-P27 -> 93839
A28: 45466 | G28: =SUM(E28:F28) -> 0 | I28: =I27+G28 -> 97339 | J28: 45466 | P28: =P27+N28 -> 3500 | Q28: =I28-P28 -> 93839
A29: 45467 | G29: =SUM(E29:F29) -> 0 | I29: =I28+G29 -> 97339 | J29: 45467 | P29: =P28+N29 -> 3500 | Q29: =I29-P29 -> 93839
A30: 45468 | G30: =SUM(E30:F30) -> 0 | I30: =I29+G30 -> 97339 | J30: 45468 | P30: =P29+N30 -> 3500 | Q30: =I30-P30 -> 93839
A31: 45469 | G31: =SUM(E31:F31) -> 0 | I31: =I30+G31 -> 97339 | J31: 45469 | P31: =P30+N31 -> 3500 | Q31: =I31-P31 -> 93839
A32: 45470 | G32: =SUM(E32:F32) -> 0 | I32: =I31+G32 -> 97339 | J32: 45470 | P32: =P31+N32 -> 3500 | Q32: =I32-P32 -> 93839
A33: 45471 | B33: ICICI | C33: NFS/S1ACAG49/CASH WDL/28-06-23 | D33: 4 | F33: 10000 | G33: =SUM(E33:F33) -> 10000 | I33: =I32+G33 -> 107339 | J33: 45471 | P33: =P32+N33 -> 3500 | Q33: =I33-P33 -> 103839
A34: 45472 | G34: =SUM(E34:F34) -> 0 | I34: =I33+G34 -> 107339 | J34: 45472 | P34: =P33+N34 -> 3500 | Q34: =I34-P34 -> 103839
A35: 45473 | G35: =SUM(E35:F35) -> 0 | I35: =I34+G35 -> 107339 | J35: 45473 | K35: Balance | L35: C/F | N35: =Q34 -> 103839 | P35: =P34+N35 -> 107339 | Q35: =I35-P35 -> 0
H37: =SUM(H6:H36) -> 0 | O37: =SUM(O6:O36) -> 6930

Sheet Jul
A2: CB2025-2026.xlsx | C2: Anurag-Professional | D2: Status: | E2: Individual | G2: CASHBOOK | I2: PAN: | J2: AFIPG7802B | L2: Asst.Yr. | N2: Month | O2: =CHOOSE(MONTH(A6),"Jan","Feb","Mar","Apr","May","Jun","Jul","Aug","Sep","Oct","Nov","Dec") -> Jul
A4: Date | B4: Reciept A/c | C4: Reciept Particulars | D4: L.F. No. | E4: VNH | F4: Cash | G4: Cash | H4: Chq. | I4: Total | J4: Date | K4: Payment A/c | L4: Payment Particulars | M4: L.F. No. | N4: Cash | O4: Chq. | P4: Total | Q4: Balance
A6: 45474 | B6: Balance | C6: B/F | F6: =Jun!N35 -> 103839 | G6: =Jun!N35 -> 103839 | I6: =I5+G6 -> 103839 | J6: 45474 | P6: =P5+N6 -> 0 | Q6: =I6-P6 -> 103839
A7: 45475 | G7: =SUM(E7:F7) -> 0 | I7: =I6+G7 -> 103839 | J7: 45475 | P7: =P6+N7 -> 0 | Q7: =I7-P7 -> 103839
A8: 45476 | G8: =SUM(E8:F8) -> 0 | I8: =I7+G8 -> 103839 | J8: 45476 | P8: =P7+N8 -> 0 | Q8: =I8-P8 -> 103839
A9: 45477 | G9: =SUM(E9:F9) -> 0 | I9: =I8+G9 -> 103839 | J9: 45477 | K9: Salary | L9: Neeraj | M9: 9 | N9: 3000 | P9: =P8+N9 -> 3000 | Q9: =I9-P9 -> 100839
A10: 45478 | B10: Patients | C10: TRF/SHRI MARUTI NANDAN/004980/ICI/22.06.2024 | G10: =SUM(E10:F10) -> 0 | H10: =2340*1.1 -> 2574 | I10: =I9+G10 -> 103839 | J10: 45478 | K10: ICICI | L10: TRF/SHRI MARUTI NANDAN/004980/ICI/22.06.2024 | O10: 2340 | P10: =P9+N10 -> 3000 | Q10: =I10-P10 -> 100839
A11: 45478 | G11: =SUM(E11:F11) -> 0 | I11: =I10+G11 -> 103839 | J11: 45478 | K11: TDStoIT | O11: 234 | P11: =P10+N11 -> 3000 | Q11: =I11-P11 -> 100839
A12: 45478 | B12: Patients | C12: TRF/SHRI MARUTINANDAN HEALTH/004964/ICI/21.06.2024 | G12: =SUM(E12:F12) -> 0 | H12: =2430*1.1 -> 2673 | I12: =I11+G12 -> 103839 | J12: 45478 | K12: ICICI | L12: TRF/SHRI MARUTINANDAN HEALTH/004964/ICI/21.06.2024 | O12: 2430 | P12: =P11+N12 -> 3000 | Q12: =I12-P12 -> 100839
A13: 45478 | G13: =SUM(E13:F13) -> 0 | I13: =I12+G13 -> 103839 | J13: 45478 | K13: TDStoIT | O13: 243 | P13: =P12+N13 -> 3000 | Q13: =I13-P13 -> 100839
A14: 45482 | G14: =SUM(E14:F14) -> 0 | I14: =I13+G14 -> 103839 | J14: 45482 | P14: =P13+N14 -> 3000 | Q14: =I14-P14 -> 100839
A15: 45483 | G15: =SUM(E15:F15) -> 0 | I15: =I14+G15 -> 103839 | J15: 45483 | P15: =P14+N15 -> 3000 | Q15: =I15-P15 -> 100839
A16: 45484 | G16: =SUM(E16:F16) -> 0 | I16: =I15+G16 -> 103839 | J16: 45484 | K16: Veh. Exp. | L16: Petrol | M16: 11 | N16: 500 | P16: =P15+N16 -> 3500 | Q16: =I16-P16 -> 100339
A17: 45485 | G17: =SUM(E17:F17) -> 0 | I17: =I16+G17 -> 103839 | J17: 45485 | P17: =P16+N17 -> 3500 | Q17: =I17-P17 -> 100339
A18: 45486 | G18: =SUM(E18:F18) -> 0 | I18: =I17+G18 -> 103839 | J18: 45486 | P18: =P17+N18 -> 3500 | Q18: =I18-P18 -> 100339
A19: 45487 | G19: =SUM(E19:F19) -> 0 | I19: =I18+G19 -> 103839 | J19: 45487 | P19: =P18+N19 -> 3500 | Q19: =I19-P19 -> 100339
A20: 45488 | G20: =SUM(E20:F20) -> 0 | I20: =I19+G20 -> 103839 | J20: 45488 | P20: =P19+N20 -> 3500 | Q20: =I20-P20 -> 100339
A21: 45489 | G21: =SUM(E21:F21) -> 0 | I21: =I20+G21 -> 103839 | J21: 45489 | P21: =P20+N21 -> 3500 | Q21: =I21-P21 -> 100339
A22: 45490 | G22: =SUM(E22:F22) -> 0 | I22: =I21+G22 -> 103839 | J22: 45490 | P22: =P21+N22 -> 3500 | Q22: =I22-P22 -> 100339
A23: 45491 | G23: =SUM(E23:F23) -> 0 | I23: =I22+G23 -> 103839 | J23: 45491 | P23: =P22+N23 -> 3500 | Q23: =I23-P23 -> 100339
A24: 45492 | G24: =SUM(E24:F24) -> 0 | I24: =I23+G24 -> 103839 | J24: 45492 | P24: =P23+N24 -> 3500 | Q24: =I24-P24 -> 100339
A25: 45493 | G25: =SUM(E25:F25) -> 0 | I25: =I24+G25 -> 103839 | J25: 45493 | P25: =P24+N25 -> 3500 | Q25: =I25-P25 -> 100339
A26: 45494 | G26: =SUM(E26:F26) -> 0 | I26: =I25+G26 -> 103839 | J26: 45494 | P26: =P25+N26 -> 3500 | Q26: =I26-P26 -> 100339
A27: 45495 | G27: =SUM(E27:F27) -> 0 | I27: =I26+G27 -> 103839 | J27: 45495 | P27: =P26+N27 -> 3500 | Q27: =I27-P27 -> 100339
A28: 45496 | G28: =SUM(E28:F28) -> 0 | I28: =I27+G28 -> 103839 | J28: 45496 | K28: Salary | L28: Gaurav | M28: 9 | N28: 3000 | P28: =P27+N28 -> 6500 | Q28: =I28-P28 -> 97339
A29: 45497 | B29: Patients | C29: CLG/SHRI MARUTI/278050/CAB/18.07.2024 | G29: =SUM(E29:F29) -> 0 | H29: =2430*1.1 -> 2673 | I29: =I28+G29 -> 103839 | J29: 45497 | K29: ICICI | L29: CLG/SHRI MARUTI/278050/CAB/18.07.2024 | M29: 4 | O29: 2430 | P29: =P28+N29 -> 6500 | Q29: =I29-P29 -> 97339
A30: 45497 | G30: =SUM(E30:F30) -> 0 | I30: =I29+G30 -> 103839 | J30: 45497 | K30: TDStoIT | M30: 10 | O30: 243 | P30: =P29+N30 -> 6500 | Q30: =I30-P30 -> 97339
A31: 45497 | B31: Patients | C31: CLG/SHRI MARUTI/278048/CAB/18.07.2024 | G31: =SUM(E31:F31) -> 0 | H31: =3780*1.1 -> 4158 | I31: =I30+G31 -> 103839 | J31: 45497 | K31: ICICI | L31: CLG/SHRI MARUTI/278048/CAB/18.07.2024 | M31: 4 | O31: 3780 | P31: =P30+N31 -> 6500 | Q31: =I31-P31 -> 97339
A32: 45497 | G32: =SUM(E32:F32) -> 0 | I32: =I31+G32 -> 103839 | J32: 45497 | K32: TDStoIT | M32: 10 | O32: 378 | P32: =P31+N32 -> 6500 | Q32: =I32-P32 -> 97339
A33: 45501 | G33: =SUM(E33:F33) -> 0 | I33: =I32+G33 -> 103839 | J33: 45501 | P33: =P32+N33 -> 6500 | Q33: =I33-P33 -> 97339
A34: 45502 | G34: =SUM(E34:F34) -> 0 | I34: =I33+G34 -> 103839 | J34: 45502 | K34: Veh. Exp. | L34: Petrol | M34: 11 | N34: 500 | P34: =P33+N34 -> 7000 | Q34: =I34-P34 -> 96839
A35: 45503 | B35: ICICI | C35: ATM/S1CNQ071/CASH WDL/29-07-23 | D35: 4 | F35: 10000 | G35: =SUM(E35:F35) -> 10000 | I35: =I34+G35 -> 113839 | J35: 45503 | P35: =P34+N35 -> 7000 | Q35: =I35-P35 -> 106839
A36: 45504 | G36: =SUM(E36:F36) -> 0 | I36: =I35+G36 -> 113839 | J36: 45504 | P36: =P35+N36 -> 7000 | Q36: =I36-P36 -> 106839
A37: 45504 | G37: =SUM(E37:F37) -> 0 | I37: =I36+G37 -> 113839 | J37: 45504 | K37: Balance | L37: C/F | N37: =Q36 -> 106839 | P37: =P36+N37 -> 113839 | Q37: =I37-P37 -> 0
H39: =SUM(H6:H37) -> 12078 | O39: =SUM(O6:O37) -> 12078

Sheet Aug
A2: CB2025-2026.xlsx | C2: Anurag-Professional | D2: Status: | E2: Individual | G2: CASHBOOK | I2: PAN: | J2: AFIPG7802B | L2: Asst.Yr. | N2: Month | O2: =CHOOSE(MONTH(A6),"Jan","Feb","Mar","Apr","May","Jun","Jul","Aug","Sep","Oct","Nov","Dec") -> Aug
A4: Date | B4: Reciept A/c | C4: Reciept Particulars | D4: L.F. No. | E4: VNH | F4: Cash | G4: Cash | H4: Chq. | I4: Total | J4: Date | K4: Payment A/c | L4: Payment Particulars | M4: L.F. No. | N4: Cash | O4: Chq. | P4: Total | Q4: Balance
A6: 45505 | B6: Balance | C6: B/F | F6: =Jul!N37 -> 106839 | G6: =Jul!N37 -> 106839 | I6: =I5+G6 -> 106839 | J6: 45505 | P6: =P5+N6 -> 0 | Q6: =I6-P6 -> 106839
A7: 45506 | G7: =SUM(E7:F7) -> 0 | I7: =I6+G7 -> 106839 | J7: 45506 | K7: Salary | L7: Neeraj | M7: 9 | N7: 3000 | P7: =P6+N7 -> 3000 | Q7: =I7-P7 -> 103839
A8: 45507 | G8: =SUM(E8:F8) -> 0 | I8: =I7+G8 -> 106839 | J8: 45507 | P8: =P7+N8 -> 3000 | Q8: =I8-P8 -> 103839
A9: 45508 | G9: =SUM(E9:F9) -> 0 | I9: =I8+G9 -> 106839 | J9: 45508 | P9: =P8+N9 -> 3000 | Q9: =I9-P9 -> 103839
A10: 45509 | G10: =SUM(E10:F10) -> 0 | I10: =I9+G10 -> 106839 | J10: 45509 | P10: =P9+N10 -> 3000 | Q10: =I10-P10 -> 103839
A11: 45510 | G11: =SUM(E11:F11) -> 0 | I11: =I10+G11 -> 106839 | J11: 45510 | P11: =P10+N11 -> 3000 | Q11: =I11-P11 -> 103839
A12: 45511 | G12: =SUM(E12:F12) -> 0 | I12: =I11+G12 -> 106839 | J12: 45511 | P12: =P11+N12 -> 3000 | Q12: =I12-P12 -> 103839
A13: 45512 | G13: =SUM(E13:F13) -> 0 | I13: =I12+G13 -> 106839 | J13: 45512 | P13: =P12+N13 -> 3000 | Q13: =I13-P13 -> 103839
A14: 45513 | G14: =SUM(E14:F14) -> 0 | I14: =I13+G14 -> 106839 | J14: 45513 | P14: =P13+N14 -> 3000 | Q14: =I14-P14 -> 103839
A15: 45514 | G15: =SUM(E15:F15) -> 0 | I15: =I14+G15 -> 106839 | J15: 45514 | P15: =P14+N15 -> 3000 | Q15: =I15-P15 -> 103839
A16: 45515 | G16: =SUM(E16:F16) -> 0 | I16: =I15+G16 -> 106839 | J16: 45515 | P16: =P15+N16 -> 3000 | Q16: =I16-P16 -> 103839
A17: 45516 | G17: =SUM(E17:F17) -> 0 | I17: =I16+G17 -> 106839 | J17: 45516 | P17: =P16+N17 -> 3000 | Q17: =I17-P17 -> 103839
A18: 45517 | G18: =SUM(E18:F18) -> 0 | I18: =I17+G18 -> 106839 | J18: 45517 | P18: =P17+N18 -> 3000 | Q18: =I18-P18 -> 103839
A19: 45518 | G19: =SUM(E19:F19) -> 0 | I19: =I18+G19 -> 106839 | J19: 45518 | P19: =P18+N19 -> 3000 | Q19: =I19-P19 -> 103839
... A26: 45525 | G26: =SUM(E26:F26) -> 0 | I26: =I25+G26 -> 106839 | J26: 45525 | P26: =P25+N26 -> 3000 | Q26: =I26-P26 -> 103839
A27: 45526 | B27: Patients | C27: TRF/SHRI MARUTINANDAN HEALTH/005057/ICI/27.07.2024 | D27: 8 | G27: =SUM(E27:F27) -> 0 | H27: =18180*1.1 -> 19998 | I27: =I26+G27 -> 106839 | J27: 45526 | K27: ICICI | L27: TRF/SHRI MARUTINANDAN HEALTH/005057/ICI/27.07.2024 | M27: 4 | O27: 18180 | P27: =P26+N27 -> 3000 | Q27: =I27-P27 -> 103839
A28: 45526 | G28: =SUM(E28:F28) -> 0 | I28: =I27+G28 -> 106839 | J28: 45526 | K28: TDStoIT | M28: 10 | O28: 1818 | P28: =P27+N28 -> 3000 | Q28: =I28-P28 -> 103839
A29: 45527 | B29: Patients | C29: CLG/SHRI MARUTI NANDAN/278144/CAB/08.08.2024 | D29: 8 | G29: =SUM(E29:F29) -> 0 | H29: =11160*1.1 -> 12276 | I29: =I28+G29 -> 106839 | J29: 45527 | K29: ICICI | L29: CLG/SHRI MARUTI NANDAN/278144/CAB/08.08.2024 | M29: 4 | O29: 11160 | P29: =P28+N29 -> 3000 | Q29: =I29-P29 -> 103839
A30: 45527 | G30: =SUM(E30:F30) -> 0 | I30: =I29+G30 -> 106839 | J30: 45527 | K30: TDStoIT | M30: 10 | O30: 1116 | P30: =P29+N30 -> 3000 | Q30: =I30-P30 -> 103839
A31: 45530 | G31: =SUM(E31:F31) -> 0 | I31: =I30+G31 -> 106839 | J31: 45530 | P31: =P30+N31 -> 3000 | Q31: =I31-P31 -> 103839
A32: 45531 | G32: =SUM(E32:F32) -> 0 | I32: =I31+G32 -> 106839 | J32: 45531 | K32: Veh. Exp. | L32: Petrol | M32: 11 | N32: 500 | P32: =P31+N32 -> 3500 | Q32: =I32-P32 -> 103339
A33: 45532 | G33: =SUM(E33:F33) -> 0 | I33: =I32+G33 -> 106839 | J33: 45532 | P33: =P32+N33 -> 3500 | Q33: =I33-P33 -> 103339
A34: 45533 | B34: ICICI | C34: NFS/ID131801/CASH WDL/28-08-23 | D34: 4 | F34: 10000 | G34: =SUM(E34:F34) -> 10000 | I34: =I33+G34 -> 116839 | J34: 45533 | P34: =P33+N34 -> 3500 | Q34: =I34-P34 -> 113339
A35: 45534 | G35: =SUM(E35:F35) -> 0 | I35: =I34+G35 -> 116839 | J35: 45534 | P35: =P34+N35 -> 3500 | Q35: =I35-P35 -> 113339
A36: 45535 | G36: =SUM(E36:F36) -> 0 | I36: =I35+G36 -> 116839 | J36: 45535 | P36: =P35+N36 -> 3500 | Q36: =I36-P36 -> 113339
A37: 45535 | G37: =SUM(E37:F37) -> 0 | I37: =I36+G37 -> 116839 | J37: 45535 | K37: Balance | L37: C/F | N37: =Q36 -> 113339 | P37: =P36+N37 -> 116839 | Q37: =I37-P37 -> 0
H39: =SUM(H6:H37) -> 32274 | O39: =SUM(O6:O37) -> 32274

Sheet Sep
A2: CB2025-2026.xlsx | C2: Anurag-Professional | D2: Status: | E2: Individual | G2: CASHBOOK | I2: PAN: | J2: AFIPG7802B | L2: Asst.Yr. | N2: Month | O2: =CHOOSE(MONTH(A6),"Jan","Feb","Mar","Apr","May","Jun","Jul","Aug","Sep","Oct","Nov","Dec") -> Sep
A4: Date | B4: Reciept A/c | C4: Reciept Particulars | D4: L.F. No. | E4: VNH | F4: Cash | G4: Cash | H4: Chq. | I4: Total | J4: Date | K4: Payment A/c | L4: Payment Particulars | M4: L.F. No. | N4: Cash | O4: Chq. | P4: Total | Q4: Balance
A6: 45536 | B6: Balance | C6: B/F | F6: =Aug!N37 -> 113339 | G6: =Aug!N37 -> 113339 | I6: =I5+G6 -> 113339 | J6: 45536 | P6: =P5+N6 -> 0 | Q6: =I6-P6 -> 113339
A7: 45537 | G7: =SUM(E7:F7) -> 0 | I7: =I6+G7 -> 113339 | J7: 45537 | K7: Salary | L7: Neeraj | M7: 9 | N7: 3000 | P7: =P6+N7 -> 3000 | Q7: =I7-P7 -> 110339
A8: 45538 | G8: =SUM(E8:F8) -> 0 | I8: =I7+G8 -> 113339 | J8: 45538 | P8: =P7+N8 -> 3000 | Q8: =I8-P8 -> 110339
A9: 45539 | G9: =SUM(E9:F9) -> 0 | I9: =I8+G9 -> 113339 | J9: 45539 | P9: =P8+N9 -> 3000 | Q9: =I9-P9 -> 110339
A10: 45540 | G10: =SUM(E10:F10) -> 0 | I10: =I9+G10 -> 113339 | J10: 45540 | P10: =P9+N10 -> 3000 | Q10: =I10-P10 -> 110339
A11: 45541 | G11: =SUM(E11:F11) -> 0 | I11: =I10+G11 -> 113339 | J11: 45541 | P11: =P10+N11 -> 3000 | Q11: =I11-P11 -> 110339
A12: 45542 | G12: =SUM(E12:F12) -> 0 | I12: =I11+G12 -> 113339 | J12: 45542 | P12: =P11+N12 -> 3000 | Q12: =I12-P12 -> 110339
A13: 45543 | G13: =SUM(E13:F13) -> 0 | I13: =I12+G13 -> 113339 | J13: 45543 | P13: =P12+N13 -> 3000 | Q13: =I13-P13 -> 110339
A14: 45544 | G14: =SUM(E14:F14) -> 0 | I14: =I13+G14 -> 113339 | J14: 45544 | P14: =P13+N14 -> 3000 | Q14: =I14-P14 -> 110339
A15: 45545 | G15: =SUM(E15:F15) -> 0 | I15: =I14+G15 -> 113339 | J15: 45545 | P15: =P14+N15 -> 3000 | Q15: =I15-P15 -> 110339
A16: 45546 | G16: =SUM(E16:F16) -> 0 | I16: =I15+G16 -> 113339 | J16: 45546 | P16: =P15+N16 -> 3000 | Q16: =I16-P16 -> 110339
A17: 45547 | G17: =SUM(E17:F17) -> 0 | I17: =I16+G17 -> 113339 | J17: 45547 | P17: =P16+N17 -> 3000 | Q17: =I17-P17 -> 110339
A18: 45548 | G18: =SUM(E18:F18) -> 0 | I18: =I17+G18 -> 113339 | J18: 45548 | K18: Veh. Exp. | L18: Petrol | M18: 11 | N18: 2000 | P18: =P17+N18 -> 5000 | Q18: =I18-P18 -> 108339
A19: 45549 | G19: =SUM(E19:F19) -> 0 | I19: =I18+G19 -> 113339 | J19: 45549 | P19: =P18+N19 -> 5000 | Q19: =I19-P19 -> 108339
A20: 45550 | G20: =SUM(E20:F20) -> 0 | I20: =I19+G20 -> 113339 | J20: 45550 | P20: =P19+N20 -> 5000 | Q20: =I20-P20 -> 108339
A21: 45551 | G21: =SUM(E21:F21) -> 0 | I21: =I20+G21 -> 113339 | J21: 45551 | P21: =P20+N21 -> 5000 | Q21: =I21-P21 -> 108339
A22: 45552 | B22: ICICI | C22: NFS/S1ACAG49/CASH WDL/17-09-23 | D22: 4 | F22: 10000 | G22: =SUM(E22:F22) -> 10000 | I22: =I21+G22 -> 123339 | J22: 45552 | P22: =P21+N22 -> 5000 | Q22: =I22-P22 -> 118339
A23: 45553 | G23: =SUM(E23:F23) -> 0 | I23: =I22+G23 -> 123339 | J23: 45553 | P23: =P22+N23 -> 5000 | Q23: =I23-P23 -> 118339
A24: 45554 | G24: =SUM(E24:F24) -> 0 | I24: =I23+G24 -> 123339 | J24: 45554 | P24: =P23+N24 -> 5000 | Q24: =I24-P24 -> 118339
A25: 45555 | G25: =SUM(E25:F25) -> 0 | I25: =I24+G25 -> 123339 | J25: 45555 | K25: Salary | L25: Gaurav | M25: 9 | N25: 3000 | P25: =P24+N25 -> 8000 | Q25: =I25-P25 -> 115339
A26: 45556 | G26: =SUM(E26:F26) -> 0 | I26: =I25+G26 -> 123339 | J26: 45556 | P26: =P25+N26 -> 8000 | Q26: =I26-P26 -> 115339
A27: 45557 | G27: =SUM(E27:F27) -> 0 | I27: =I26+G27 -> 123339 | J27: 45557 | P27: =P26+N27 -> 8000 | Q27: =I27-P27 -> 115339
A28: 45558 | G28: =SUM(E28:F28) -> 0 | I28: =I27+G28 -> 123339 | J28: 45558 | P28: =P27+N28 -> 8000 | Q28: =I28-P28 -> 115339
A29: 45559 | G29: =SUM(E29:F29) -> 0 | I29: =I28+G29 -> 123339 | J29: 45559 | P29: =P28+N29 -> 8000 | Q29: =I29-P29 -> 115339
A30: 45560 | G30: =SUM(E30:F30) -> 0 | I30: =I29+G30 -> 123339 | J30: 45560 | P30: =P29+N30 -> 8000 | Q30: =I30-P30 -> 115339
A31: 45561 | G31: =SUM(E31:F31) -> 0 | I31: =I30+G31 -> 123339 | J31: 45561 | P31: =P30+N31 -> 8000 | Q31: =I31-P31 -> 115339
A32: 45562 | G32: =SUM(E32:F32) -> 0 | I32: =I31+G32 -> 123339 | J32: 45562 | P32: =P31+N32 -> 8000 | Q32: =I32-P32 -> 115339
A33: 45563 | G33: =SUM(E33:F33) -> 0 | I33: =I32+G33 -> 123339 | J33: 45563 | K33: Veh. Exp. | L33: Petrol | M33: 11 | N33: 500 | P33: =P32+N33 -> 8500 | Q33: =I33-P33 -> 114839
A34: 45564 | G34: =SUM(E34:F34) -> 0 | I34: =I33+G34 -> 123339 | J34: 45564 | P34: =P33+N34 -> 8500 | Q34: =I34-P34 -> 114839
A35: 45565 | G35: =SUM(E35:F35) -> 0 | I35: =I34+G35 -> 123339 | J35: 45565 | K35: Balance | L35: C/F | N35: =Q34 -> 114839 | P35: =P34+N35 -> 123339 | Q35: =I35-P35 -> 0
H37: =SUM(H6:H35) -> 0 | I37: =J40+G37 -> 0 | O37: =SUM(O6:O35) -> 0

Sheet Oct
A2: CB2025-2026.xlsx | C2: Anurag-Professional | D2: Status: | E2: Individual | G2: CASHBOOK | I2: PAN: | J2: AFIPG7802B | L2: Asst.Yr. | N2: Month | O2: =CHOOSE(MONTH(A6),"Jan","Feb","Mar","Apr","May","Jun","Jul","Aug","Sep","Oct","Nov","Dec") -> Oct
A4: Date | B4: Reciept A/c | C4: Reciept Particulars | D4: L.F. No. | E4: VNH | F4: Cash | G4: Cash | H4: Chq. | I4: Total | J4: Date | K4: Payment A/c | L4: Payment Particulars | M4: L.F. No. | N4: Cash | O4: Chq. | P4: Total | Q4: Balance
A6: 45566 | B6: Balance | C6: B/F | F6: =Sep!N35 -> 114839 | G6: =Sep!N35 -> 114839 | I6: =I5+G6 -> 114839 | J6: 45566 | P6: =P5+N6 -> 0 | Q6: =I6-P6 -> 114839
A7: 45567 | G7: =SUM(E7:F7) -> 0 | I7: =I6+G7 -> 114839 | J7: 45567 | K7: Veh. Exp. | L7: Petrol | M7: 9 | N7: 1000 | P7: =P6+N7 -> 1000 | Q7: =I7-P7 -> 113839
A8: 45568 | B8: Patients | C8: TRFR FROM: SHRI MARUTINANDAN HEALTHCARE PRIVATE LI | D8: 8 | G8: =SUM(E8:F8) -> 0 | H8: =2520*1.1 -> 2772 | I8: =I7+G8 -> 114839 | J8: 45568 | K8: ICICI | L8: TRFR FROM: SHRI MARUTINANDAN HEALTHCARE PRIVATE LI | M8: 4 | O8: 2520 | P8: =P7+N8 -> 1000 | Q8: =I8-P8 -> 113839
A9: 45568 | G9: =SUM(E9:F9) -> 0 | I9: =I8+G9 -> 114839 | J9: 45568 | K9: TDStoIT | M9: 10 | O9: 252 | P9: =P8+N9 -> 1000 | Q9: =I9-P9 -> 113839
A10: 45568 | B10: Patients | C10: TRFR FROM: SHRI MARUTINANDAN HEALTHCARE PRIVATE LI | D10: 8 | G10: =SUM(E10:F10) -> 0 | H10: =5400*1.1 -> 5940 | I10: =I9+G10 -> 114839 | J10: 45568 | K10: ICICI | L10: TRFR FROM: SHRI MARUTINANDAN HEALTHCARE PRIVATE LI | M10: 4 | O10: 5400 | P10: =P9+N10 -> 1000 | Q10: =I10-P10 -> 113839
A11: 45568 | G11: =SUM(E11:F11) -> 0 | I11: =I10+G11 -> 114839 | J11: 45568 | K11: TDStoIT | M11: 10 | O11: 540 | P11: =P10+N11 -> 1000 | Q11: =I11-P11 -> 113839
A12: 45568 | B12: Patients | C12: TRFR FROM: SHRI MARUTINANDAN HEALTHCARE PRIVATE LI | D12: 8 | G12: =SUM(E12:F12) -> 0 | H12: =4140*1.1 -> 4554 | I12: =I11+G12 -> 114839 | J12: 45568 | K12: ICICI | L12: TRFR FROM: SHRI MARUTINANDAN HEALTHCARE PRIVATE LI | M12: 4 | O12: 4140 | P12: =P11+N12 -> 1000 | Q12: =I12-P12 -> 113839
A13: 45568 | G13: =SUM(E13:F13) -> 0 | I13: =I12+G13 -> 114839 | J13: 45568 | K13: TDStoIT | M13: 10 | O13: 414 | P13: =P12+N20 -> 1500 | Q13: =I13-P13 -> 113339
A14: 45574 | G14: =SUM(E14:F14) -> 0 | I14: =I13+G14 -> 114839 | J14: 45574 | P14: =P13+N21 -> 1500 | Q14: =I14-P14 -> 113339
A15: 45575 | G15: =SUM(E15:F15) -> 0 | I15: =I14+G15 -> 114839 | J15: 45575 | P15: =P14+N15 -> 1500 | Q15: =I15-P15 -> 113339
A16: 45576 | G16: =SUM(E16:F16) -> 0 | I16: =I15+G16 -> 114839 | J16: 45576 | P16: =P15+N16 -> 1500 | Q16: =I16-P16 -> 113339
A17: 45577 | G17: =SUM(E17:F17) -> 0 | I17: =I16+G17 -> 114839 | J17: 45577 | P17: =P16+N17 -> 1500 | Q17: =I17-P17 -> 113339
A18: 45578 | G18: =SUM(E18:F18) -> 0 | I18: =I17+G18 -> 114839 | J18: 45578 | P18: =P17+N18 -> 1500 | Q18: =I18-P18 -> 113339
A19: 45579 | G19: =SUM(E19:F19) -> 0 | I19: =I18+G19 -> 114839 | J19: 45579 | P19: =P18+N19 -> 1500 | Q19: =I19-P19 -> 113339
A20: 45580 | G20: =SUM(E20:F20) -> 0 | I20: =I19+G20 -> 114839 | J20: 45580 | K20: Veh. Exp. | L20: Petrol | M20: 11 | N20: 500 | P20: =P19+N20 -> 2000 | Q20: =I20-P20 -> 112839
A21: 45581 | G21: =SUM(E21:F21) -> 0 | I21: =I20+G21 -> 114839 | J21: 45581 | P21: =P20+N21 -> 2000 | Q21: =I21-P21 -> 112839
A22: 45582 | G22: =SUM(E22:F22) -> 0 | I22: =I21+G22 -> 114839 | J22: 45582 | P22: =P21+N22 -> 2000 | Q22: =I22-P22 -> 112839
A23: 45583 | G23: =SUM(E23:F23) -> 0 | I23: =I22+G23 -> 114839 | J23: 45583 | P23: =P22+N23 -> 2000 | Q23: =I23-P23 -> 112839
A24: 45584 | G24: =SUM(E24:F24) -> 0 | I24: =I23+G24 -> 114839 | J24: 45584 | P24: =P23+N24 -> 2000 | Q24: =I24-P24 -> 112839
A25: 45585 | G25: =SUM(E25:F25) -> 0 | I25: =I24+G25 -> 114839 | J25: 45585 | K25: Salary | L25: Gaurav | M25: 9 | N25: 3000 | P25: =P24+N25 -> 5000 | Q25: =I25-P25 -> 109839
A26: 45586 | G26: =SUM(E26:F26) -> 0 | I26: =I25+G26 -> 114839 | J26: 45586 | P26: =P25+N26 -> 5000 | Q26: =I26-P26 -> 109839
A27: 45587 | B27: ICICI | C27: NFS/CASH WDL/329515011779/S1ACAG49/AGRA /22-10 | D27: 4 | F27: 5000 | G27: =SUM(E27:F27) -> 5000 | I27: =I26+G27 -> 119839 | J27: 45587 | P27: =P26+N27 -> 5000 | Q27: =I27-P27 -> 114839
A28: 45588 | G28: =SUM(E28:F28) -> 0 | I28: =I27+G28 -> 119839 | J28: 45588 | P28: =P27+N28 -> 5000 | Q28: =I28-P28 -> 114839
A29: 45589 | G29: =SUM(E29:F29) -> 0 | I29: =I28+G29 -> 119839 | J29: 45589 | P29: =P28+N29 -> 5000 | Q29: =I29-P29 -> 114839
A30: 45590 | G30: =SUM(E30:F30) -> 0 | I30: =I29+G30 -> 119839 | J30: 45590 | K30: Veh. Exp. | L30: Petrol | M30: 11 | N30: 500 | P30: =P29+N30 -> 5500 | Q30: =I30-P30 -> 114339
A31: 45591 | G31: =SUM(E31:F31) -> 0 | I31: =I30+G31 -> 119839 | J31: 45591 | P31: =P30+N31 -> 5500 | Q31: =I31-P31 -> 114339
A32: 45592 | G32: =SUM(E32:F32) -> 0 | I32: =I31+G32 -> 119839 | J32: 45592 | P32: =P31+N32 -> 5500 | Q32: =I32-P32 -> 114339
A33: 45593 | G33: =SUM(E33:F33) -> 0 | I33: =I32+G33 -> 119839 | J33: 45593 | P33: =P32+N33 -> 5500 | Q33: =I33-P33 -> 114339
A34: 45594 | G34: =SUM(E34:F34) -> 0 | I34: =I33+G34 -> 119839 | J34: 45594 | P34: =P33+N34 -> 5500 | Q34: =I34-P34 -> 114339
A35: 45595 | G35: =SUM(E35:F35) -> 0 | I35: =I34+G35 -> 119839 | J35: 45595 | P35: =P34+N35 -> 5500 | Q35: =I35-P35 -> 114339
A36: 45596 | G36: =SUM(E36:F36) -> 0 | I36: =I35+G36 -> 119839 | J36: 45596 | P36: =P35+N36 -> 5500 | Q36: =I36-P36 -> 114339
A37: 45596 | G37: =SUM(E37:F37) -> 0 | I37: =I36+G37 -> 119839 | J37: 45596 | K37: Balance | L37: C/F | N37: =Q36 -> 114339 | P37: =P36+N37 -> 119839 | Q37: =I37-P37 -> 0
H39: =SUM(H6:H37) -> 13266 | O39: =SUM(O6:O37) -> 13266

Sheet Nov
A2: CB2025-2026.xlsx | C2: Anurag-Professional | D2: Status: | E2: Individual | G2: CASHBOOK | I2: PAN: | J2: AFIPG7802B | L2: Asst.Yr. | N2: Month | O2: =CHOOSE(MONTH(A6),"Jan","Feb","Mar","Apr","May","Jun","Jul","Aug","Sep","Oct","Nov","Dec") -> Nov
A4: Date | B4: Reciept A/c | C4: Reciept Particulars | D4: L.F. No. | E4: VNH | F4: Cash | G4: Cash | H4: Chq. | I4: Total | J4: Date | K4: Payment A/c | L4: Payment Particulars | M4: L.F. No. | N4: Cash | O4: Chq. | P4: Total | Q4: Balance
A6: 45597 | B6: Balance | C6: B/F | F6: =Oct!N37 -> 114339 | G6: =Oct!N37 -> 114339 | I6: =I5+G6 -> 114339 | J6: 45597 | P6: =P5+N6 -> 0 | Q6: =I6-P6 -> 114339
A7: 45598 | G7: =SUM(E7:F7) -> 0 | I7: =I6+G7 -> 114339 | J7: 45598 | P7: =P6+N7 -> 0 | Q7: =I7-P7 -> 114339
A8: 45599 | G8: =SUM(E8:F8) -> 0 | I8: =I7+G8 -> 114339 | J8: 45599 | P8: =P7+N8 -> 0 | Q8: =I8-P8 -> 114339
A9: 45600 | G9: =SUM(E9:F9) -> 0 | I9: =I8+G9 -> 114339 | J9: 45600 | K9: Salary | L9: Neeraj | M9: 9 | N9: 3000 | P9: =P8+N9 -> 3000 | Q9: =I9-P9 -> 111339
A10: 45601 | G10: =SUM(E10:F10) -> 0 | I10: =I9+G10 -> 114339 | J10: 45601 | K10: Veh. Exp. | L10: Petrol | M10: 11 | N10: 500 | P10: =P9+N10 -> 3500 | Q10: =I10-P10 -> 110839
A11: 45602 | G11: =SUM(E11:F11) -> 0 | I11: =I10+G11 -> 114339 | J11: 45602 | P11: =P10+N11 -> 3500 | Q11: =I11-P11 -> 110839
A12: 45603 | B12: Patients | C12: UPI/akjain62@unionb/fee/Union Bank of I/110003147701/UOB0056A66CAADA437F8FFB9CCF6796D6D4 | G12: =SUM(E12:F12) -> 0 | H12: 300 | I12: =I11+G12 -> 114339 | J12: 45603 | K12: ICICI | L12: UPI/akjain62@unionb/fee/Union Bank of I/110003147701/UOB0056A66CAADA437F8FFB9CCF6796D6D4 | O12: 300 | P12: =P11+N12 -> 3500 | Q12: =I12-P12 -> 110839
A13: 45604 | G13: =SUM(E13:F13) -> 0 | I13: =I12+G13 -> 114339 | J13: 45604 | P13: =P12+N13 -> 3500 | Q13: =I13-P13 -> 110839
A14: 45605 | G14: =SUM(E14:F14) -> 0 | I14: =I13+G14 -> 114339 | J14: 45605 | P14: =P13+N14 -> 3500 | Q14: =I14-P14 -> 110839
A15: 45606 | G15: =SUM(E15:F15) -> 0 | I15: =I14+G15 -> 114339 | J15: 45606 | P15: =P14+N15 -> 3500 | Q15: =I15-P15 -> 110839
A16: 45607 | G16: =SUM(E16:F16) -> 0 | I16: =I15+G16 -> 114339 | J16: 45607 | P16: =P15+N16 -> 3500 | Q16: =I16-P16 -> 110839
A17: 45608 | G17: =SUM(E17:F17) -> 0 | I17: =I16+G17 -> 114339 | J17: 45608 | P17: =P16+N17 -> 3500 | Q17: =I17-P17 -> 110839
A18: 45609 | G18: =SUM(E18:F18) -> 0 | I18: =I17+G18 -> 114339 | J18: 45609 | P18: =P17+N18 -> 3500 | Q18: =I18-P18 -> 110839
A19: 45610 | G19: =SUM(E19:F19) -> 0 | I19: =I18+G19 -> 114339 | J19: 45610 | P19: =P18+N19 -> 3500 | Q19: =I19-P19 -> 110839
A20: 45611 | G20: =SUM(E20:F20) -> 0 | I20: =I19+G20 -> 114339 | J20: 45611 | P20: =P19+N20 -> 3500 | Q20: =I20-P20 -> 110839
A21: 45612 | G21: =SUM(E21:F21) -> 0 | I21: =I20+G21 -> 114339 | J21: 45612 | P21: =P20+N21 -> 3500 | Q21: =I21-P21 -> 110839
A22: 45613 | G22: =SUM(E22:F22) -> 0 | I22: =I21+G22 -> 114339 | J22: 45613 | K22: Salary | L22: Gaurav | M22: 9 | N22: 3000 | P22: =P21+N22 -> 6500 | Q22: =I22-P22 -> 107839
A23: 45614 | D23: 5 | G23: =SUM(E23:F23) -> 0 | I23: =I22+G23 -> 114339 | J23: 45614 | K23: ICICI | P23: =P22+N23 -> 6500 | Q23: =I23-P23 -> 107839
A24: 45615 | G24: =SUM(E24:F24) -> 0 | I24: =I23+G24 -> 114339 | J24: 45615 | K24: TDStoIT | P24: =P23+N24 -> 6500 | Q24: =I24-P24 -> 107839
A25: 45616 | G25: =SUM(E25:F25) -> 0 | I25: =I24+G25 -> 114339 | J25: 45616 | P25: =P24+N25 -> 6500 | Q25: =I25-P25 -> 107839
A26: 45617 | G26: =SUM(E26:F26) -> 0 | I26: =I25+G26 -> 114339 | J26: 45617 | P26: =P25+N26 -> 6500 | Q26: =I26-P26 -> 107839
A27: 45618 | G27: =SUM(E27:F27) -> 0 | I27: =I26+G27 -> 114339 | J27: 45618 | P27: =P26+N27 -> 6500 | Q27: =I27-P27 -> 107839
A28: 45619 | G28: =SUM(E28:F28) -> 0 | I28: =I27+G28 -> 114339 | J28: 45619 | P28: =P27+N28 -> 6500 | Q28: =I28-P28 -> 107839
A29: 45620 | G29: =SUM(E29:F29) -> 0 | I29: =I28+G29 -> 114339 | J29: 45620 | P29: =P28+N29 -> 6500 | Q29: =I29-P29 -> 107839
A30: 45621 | B30: Patients | C30: TRF/SHRI MARUTINANDAN/005255/ICI/13.10.2024 | G30: =SUM(E30:F30) -> 0 | H30: =6840*1.1 -> 7524 | I30: =I29+G30 -> 114339 | J30: 45621 | K30: ICICI | L30: TRF/SHRI MARUTINANDAN/005255/ICI/13.10.2024 | O30: 6840 | P30: =P29+N30 -> 6500 | Q30: =I30-P30 -> 107839
A31: 45621 | G31: =SUM(E31:F31) -> 0 | I31: =I30+G31 -> 114339 | J31: 45621 | K31: TDStoIT | O31: 684 | P31: =P30+N31 -> 6500 | Q31: =I31-P31 -> 107839
A32: 45622 | B32: Patients | C32: CLG/SHRI MARUTI NANDAN HEAL/278319/CAB/06.11.2024 | G32: =SUM(E32:F32) -> 0 | H32: =4140*1.1 -> 4554 | I32: =I31+G32 -> 114339 | J32: 45622 | K32: ICICI | L32: CLG/SHRI MARUTI NANDAN HEAL/278319/CAB/06.11.2024 | O32: 4140 | P32: =P31+N32 -> 6500 | Q32: =I32-P32 -> 107839
A33: 45622 | G33: =SUM(E33:F33) -> 0 | I33: =I32+G33 -> 114339 | J33: 45622 | K33: TDStoIT | O33: 414 | P33: =P32+N33 -> 6500 | Q33: =I33-P33 -> 107839
A34: 45622 | B34: Patients | C34: CLG/SHRI MARUTI NANDAN HEAL/278323/CAB/06.11.2024 | G34: =SUM(E34:F34) -> 0 | H34: =4410*1.1 -> 4851 | I34: =I33+G34 -> 114339 | J34: 45622 | K34: ICICI | L34: CLG/SHRI MARUTI NANDAN HEAL/278323/CAB/06.11.2024 | O34: 4410 | P34: =P33+N34 -> 6500 | Q34: =I34-P34 -> 107839
A35: 45622 | G35: =SUM(E35:F35) -> 0 | H35: =5400*1.1 -> 5940 | I35: =I34+G35 -> 114339 | J35: 45622 | K35: TDStoIT | O35: 441 | P35: =P34+N35 -> 6500 | Q35: =I35-P35 -> 107839
A36: 45625 | B36: Patients | C36: TRF/SHRI MARUTINANDAN HEALTH/005353/ICI/20.11.2024 | G36: =SUM(E36:F36) -> 0 | I36: =I35+G36 -> 114339 | J36: 45625 | K36: ICICI | L36: TRF/SHRI MARUTINANDAN HEALTH/005353/ICI/20.11.2024 | O36: 5400 | P36: =P35+N36 -> 6500 | Q36: =I36-P36 -> 107839
A37: 45625 | G37: =SUM(E37:F37) -> 0 | I37: =I36+G37 -> 114339 | J37: 45625 | K37: TDStoIT | O37: 540 | P37: =P36+N37 -> 6500 | Q37: =I37-P37 -> 107839
A38: 45626 | G38: =SUM(E38:F38) -> 0 | I38: =I37+G38 -> 114339 | J38: 45626 | P38: =P37+N38 -> 6500 | Q38: =I38-P38 -> 107839
A39: 45626 | G39: =SUM(E39:F39) -> 0 | I39: =I38+G39 -> 114339 | J39: 45626 | P39: =P38+N39 -> 6500 | Q39: =I39-P39 -> 107839
A40: 45626 | G40: =SUM(E40:F40) -> 0 | I40: =I39+G40 -> 114339 | J40: 45626 | K40: Balance | L40: C/F | N40: =Q39 -> 107839 | P40: =P39+N40 -> 114339 | Q40: =I40-P40 -> 0
H41: =SUM(H6:H39) -> 23169 | O41: =SUM(O6:O39) -> 23169

Sheet Dec
A2: CB2025-2026.xlsx | C2: Anurag-Professional | D2: Status: | E2: Individual | G2: CASHBOOK | I2: PAN: | J2: AFIPG7802B | L2: Asst.Yr. | N2: Month | O2: =CHOOSE(MONTH(A6),"Jan","Feb","Mar","Apr","May","Jun","Jul","Aug","Sep","Oct","Nov","Dec") -> Dec
A4: Date | B4: Reciept A/c | C4: Reciept Particulars | D4: L.F. No. | E4: VNH | F4: Cash | G4: Cash | H4: Chq. | I4: Total | J4: Date | K4: Payment A/c | L4: Payment Particulars | M4: L.F. No. | N4: Cash | O4: Chq. | P4: Total | Q4: Balance
A6: 45627 | B6: Balance | C6: B/F | F6: =Nov!N40 -> 107839 | G6: =Nov!N40 -> 107839 | I6: =I5+G6 -> 107839 | J6: 45627 | P6: =P5+N6 -> 0 | Q6: =I6-P6 -> 107839
A7: 45628 | G7: =SUM(E7:F7) -> 0 | I7: =I6+G7 -> 107839 | J7: 45628 | K7: Salary | L7: Neeraj | M7: 9 | N7: 3000 | P7: =P6+N7 -> 3000 | Q7: =I7-P7 -> 104839
A8: 45629 | G8: =SUM(E8:F8) -> 0 | I8: =I7+G8 -> 107839 | J8: 45629 | P8: =P7+N8 -> 3000 | Q8: =I8-P8 -> 104839
A9: 45630 | G9: =SUM(E9:F9) -> 0 | I9: =I8+G9 -> 107839 | J9: 45630 | P9: =P8+N9 -> 3000 | Q9: =I9-P9 -> 104839
A10: 45631 | G10: =SUM(E10:F10) -> 0 | I10: =I9+G10 -> 107839 | J10: 45631 | P10: =P9+N10 -> 3000 | Q10: =I10-P10 -> 104839
A11: 45632 | G11: =SUM(E11:F11) -> 0 | I11: =I10+G11 -> 107839 | J11: 45632 | P11: =P10+N11 -> 3000 | Q11: =I11-P11 -> 104839
A12: 45633 | G12: =SUM(E12:F12) -> 0 | I12: =I11+G12 -> 107839 | J12: 45633 | P12: =P11+N12 -> 3000 | Q12: =I12-P12 -> 104839
A13: 45634 | G13: =SUM(E13:F13) -> 0 | I13: =I12+G13 -> 107839 | J13: 45634 | P13: =P12+N13 -> 3000 | Q13: =I13-P13 -> 104839
A14: 45635 | G14: =SUM(E14:F14) -> 0 | I14: =I13+G14 -> 107839 | J14: 45635 | P14: =P13+N14 -> 3000 | Q14: =I14-P14 -> 104839
A15: 45636 | G15: =SUM(E15:F15) -> 0 | I15: =I14+G15 -> 107839 | J15: 45636 | P15: =P14+N15 -> 3000 | Q15: =I15-P15 -> 104839
A16: 45637 | G16: =SUM(E16:F16) -> 0 | I16: =I15+G16 -> 107839 | J16: 45637 | P16: =P15+N16 -> 3000 | Q16: =I16-P16 -> 104839
A17: 45638 | G17: =SUM(E17:F17) -> 0 | I17: =I16+G17 -> 107839 | J17: 45638 | P17: =P16+N17 -> 3000 | Q17: =I17-P17 -> 104839
A18: 45639 | G18: =SUM(E18:F18) -> 0 | I18: =I17+G18 -> 107839 | J18: 45639 | P18: =P17+N18 -> 3000 | Q18: =I18-P18 -> 104839
A19: 45640 | G19: =SUM(E19:F19) -> 0 | I19: =I18+G19 -> 107839 | J19: 45640 | P19: =P18+N19 -> 3000 | Q19: =I19-P19 -> 104839
A20: 45641 | G20: =SUM(E20:F20) -> 0 | I20: =I19+G20 -> 107839 | J20: 45641 | P20: =P19+N20 -> 3000 | Q20: =I20-P20 -> 104839
A21: 45642 | B21: Patients | C21: UPI/aradhanajain.77/fee/UNION BANK OF I/110004731698/UOBbb6b2e4e029846c0893e0022c618aa17 | G21: =SUM(E21:F21) -> 0 | H21: 300 | I21: =I20+G21 -> 107839 | J21: 45642 | K21: ICICI | L21: UPI/aradhanajain.77/fee/UNION BANK OF I/110004731698/UOBbb6b2e4e029846c0893e0022c618aa17 | O21: 300 | P21: =P20+N21 -> 3000 | Q21: =I21-P21 -> 104839
A22: 45643 | G22: =SUM(E22:F22) -> 0 | I22: =I21+G22 -> 107839 | J22: 45643 | P22: =P21+N22 -> 3000 | Q22: =I22-P22 -> 104839
A23: 45644 | G23: =SUM(E23:F23) -> 0 | I23: =I22+G23 -> 107839 | J23: 45644 | P23: =P22+N23 -> 3000 | Q23: =I23-P23 -> 104839
A24: 45645 | G24: =SUM(E24:F24) -> 0 | I24: =I23+G24 -> 107839 | J24: 45645 | P24: =P23+N24 -> 3000 | Q24: =I24-P24 -> 104839
A25: 45646 | G25: =SUM(E25:F25) -> 0 | I25: =I24+G25 -> 107839 | J25: 45646 | P25: =P24+N25 -> 3000 | Q25: =I25-P25 -> 104839
A26: 45647 | G26: =SUM(E26:F26) -> 0 | I26: =I25+G26 -> 107839 | J26: 45647 | K26: Salary | L26: Gaurav | M26: 9 | N26: 3000 | P26: =P25+N26 -> 6000 | Q26: =I26-P26 -> 101839
A27: 45648 | G27: =SUM(E27:F27) -> 0 | I27: =I26+G27 -> 107839 | J27: 45648 | P27: =P26+N27 -> 6000 | Q27: =I27-P27 -> 101839
A28: 45649 | G28: =SUM(E28:F28) -> 0 | I28: =I27+G28 -> 107839 | J28: 45649 | P28: =P27+N28 -> 6000 | Q28: =I28-P28 -> 101839
A29: 45650 | G29: =SUM(E29:F29) -> 0 | I29: =I28+G29 -> 107839 | J29: 45650 | P29: =P28+N29 -> 6000 | Q29: =I29-P29 -> 101839
A30: 45651 | G30: =SUM(E30:F30) -> 0 | I30: =I29+G30 -> 107839 | J30: 45651 | P30: =P29+N30 -> 6000 | Q30: =I30-P30 -> 101839
A31: 45652 | B31: Patients | C31: UPI/aradhanajain.77/fee/UNION BANK OF I/110005115377/UOB8b5a3fb3b56040ac9f1cb2856b871638 | D31: 8 | G31: =SUM(E31:F31) -> 0 | H31: 300 | I31: =I30+G31 -> 107839 | J31: 45652 | K31: ICICI | L31: UPI/aradhanajain.77/fee/UNION BANK OF I/110005115377/UOB8b5a3fb3b56040ac9f1cb2856b871638 | M31: 4 | O31: 300 | P31: =P30+N31 -> 6000 | Q31: =I31-P31 -> 101839
A32: 45653 | G32: =SUM(E32:F32) -> 0 | I32: =I31+G32 -> 107839 | J32: 45653 | P32: =P31+N32 -> 6000 | Q32: =I32-P32 -> 101839
A33: 45654 | G33: =SUM(E33:F33) -> 0 | I33: =I32+G33 -> 107839 | J33: 45654 | K33: Veh. Exp. | L33: Petrol | M33: 11 | N33: 500 | P33: =P32+N33 -> 6500 | Q33: =I33-P33 -> 101339
A34: 45655 | G34: =SUM(E34:F34) -> 0 | I34: =I33+G34 -> 107839 | J34: 45655 | P34: =P33+N34 -> 6500 | Q34: =I34-P34 -> 101339
A35: 45656 | B35: ICICI | C35: NFS/CASH WDL/336315013194/S1ACAG49/AGRA /29-12 | D35: 4 | F35: 10000 | G35: =SUM(E35:F35) -> 10000 | I35: =I34+G35 -> 117839 | J35: 45656 | P35: =P34+N35 -> 6500 | Q35: =I35-P35 -> 111339
A36: 45657 | G36: =SUM(E36:F36) -> 0 | I36: =I35+G36 -> 117839 | J36: 45657 | P36: =P35+N36 -> 6500 | Q36: =I36-P36 -> 111339
A37: 45657 | G37: =SUM(E37:F37) -> 0 | I37: =I36+G37 -> 117839 | J37: 45657 | K37: Balance | L37: C/F | N37: =Q36 -> 111339 | P37: =P36+N37 -> 117839 | Q37: =I37-P37 -> 0
H39: =SUM(H6:H38) -> 600 | O39: =SUM(O6:O38) -> 600

Sheet Jan
A2: CB2025-2026.xlsx | C2: Anurag-Professional | D2: Status: | E2: Individual | G2: CASHBOOK | I2: PAN: | J2: AFIPG7802B | L2: Asst.Yr. | N2: Month | O2: =CHOOSE(MONTH(A6),"Jan","Feb","Mar","Apr","May","Jun","Jul","Aug","Sep","Oct","Nov","Dec") -> Jan
A4: Date | B4: Reciept A/c | C4: Reciept Particulars | D4: L.F. No. | E4: VNH | F4: Cash | G4: Cash | H4: Chq. | I4: Total | J4: Date | K4: Payment A/c | L4: Payment Particulars | M4: L.F. No. | N4: Cash | O4: Chq. | P4: Total | Q4: Balance
A6: 45658 | B6: Balance | C6: B/F | F6: =Dec!N37 -> 111339 | G6: =Dec!N37 -> 111339 | I6: =I5+G6 -> 111339 | J6: 45658 | P6: =P5+N6 -> 0 | Q6: =I6-P6 -> 111339
A7: 45659 | G7: =SUM(E7:F7) -> 0 | I7: =I6+G7 -> 111339 | J7: 45659 | K7: Salary | L7: Neeraj | M7: 9 | N7: 3000 | P7: =P6+N7 -> 3000 | Q7: =I7-P7 -> 108339
A8: 45660 | B8: Patients | C8: CLG/SHRI MARUTI NANDAN HEAL/278417/CAB/18.12.2024 | G8: =SUM(E8:F8) -> 0 | H8: =4680*1.1 -> 5148 | I8: =I7+G8 -> 111339 | J8: 45660 | K8: ICICI | L8: CLG/SHRI MARUTI NANDAN HEAL/278417/CAB/18.12.2024 | O8: 4680 | P8: =P7+N8 -> 3000 | Q8: =I8-P8 -> 108339
A9: 45660 | G9: =SUM(E9:F9) -> 0 | I9: =I8+G9 -> 111339 | J9: 45660 | K9: TDStoIT | O9: 468 | P9: =P8+N9 -> 3000 | Q9: =I9-P9 -> 108339
A10: 45662 | G10: =SUM(E10:F10) -> 0 | I10: =I9+G10 -> 111339 | J10: 45662 | P10: =P9+N10 -> 3000 | Q10: =I10-P10 -> 108339
A11: 45663 | G11: =SUM(E11:F11) -> 0 | I11: =I10+G11 -> 111339 | J11: 45663 | P11: =P10+N11 -> 3000 | Q11: =I11-P11 -> 108339
A12: 45664 | G12: =SUM(E12:F12) -> 0 | I12: =I11+G12 -> 111339 | J12: 45664 | P12: =P11+N12 -> 3000 | Q12: =I12-P12 -> 108339
A13: 45665 | G13: =SUM(E13:F13) -> 0 | I13: =I12+G13 -> 111339 | J13: 45665 | P13: =P12+N13 -> 3000 | Q13: =I13-P13 -> 108339
A14: 45666 | G14: =SUM(E14:F14) -> 0 | I14: =I13+G14 -> 111339 | J14: 45666 | P14: =P13+N14 -> 3000 | Q14: =I14-P14 -> 108339
A15: 45667 | G15: =SUM(E15:F15) -> 0 | I15: =I14+G15 -> 111339 | J15: 45667 | P15: =P14+N15 -> 3000 | Q15: =I15-P15 -> 108339
A16: 45668 | G16: =SUM(E16:F16) -> 0 | I16: =I15+G16 -> 111339 | J16: 45668 | P16: =P15+N16 -> 3000 | Q16: =I16-P16 -> 108339
A17: 45669 | G17: =SUM(E17:F17) -> 0 | I17: =I16+G17 -> 111339 | J17: 45669 | P17: =P16+N17 -> 3000 | Q17: =I17-P17 -> 108339
A18: 45670 | G18: =SUM(E18:F18) -> 0 | I18: =I17+G18 -> 111339 | J18: 45670 | P18: =P17+N18 -> 3000 | Q18: =I18-P18 -> 108339
A19: 45671 | G19: =SUM(E19:F19) -> 0 | I19: =I18+G19 -> 111339 | J19: 45671 | P19: =P18+N19 -> 3000 | Q19: =I19-P19 -> 108339
A20: 45672 | G20: =SUM(E20:F20) -> 0 | I20: =I19+G20 -> 111339 | J20: 45672 | P20: =P19+N20 -> 3000 | Q20: =I20-P20 -> 108339
A21: 45673 | G21: =SUM(E21:F21) -> 0 | I21: =I20+G21 -> 111339 | J21: 45673 | P21: =P20+N21 -> 3000 | Q21: =I21-P21 -> 108339
... A24: 45676 | G24: =SUM(E24:F24) -> 0 | I24: =I23+G24 -> 111339 | J24: 45676 | P24: =P23+N24 -> 3000 | Q24: =I24-P24 -> 108339
A25: 45677 | G25: =SUM(E25:F25) -> 0 | I25: =I24+G25 -> 111339 | J25: 45677 | K25: Salary | L25: Gaurav | M25: 9 | N25: 3000 | P25: =P24+N25 -> 6000 | Q25: =I25-P25 -> 105339
A26: 45678 | G26: =SUM(E26:F26) -> 0 | I26: =I25+G26 -> 111339 | J26: 45678 | P26: =P25+N26 -> 6000 | Q26: =I26-P26 -> 105339
A27: 45679 | G27: =SUM(E27:F27) -> 0 | I27: =I26+G27 -> 111339 | J27: 45679 | K27: Veh. Exp. | L27: Petrol | M27: 11 | N27: 500 | P27: =P26+N27 -> 6500 | Q27: =I27-P27 -> 104839
A28: 45680 | G28: =SUM(E28:F28) -> 0 | I28: =I27+G28 -> 111339 | J28: 45680 | P28: =P27+N28 -> 6500 | Q28: =I28-P28 -> 104839
A29: 45681 | B29: Patients | C29: TRF/SHRI MURTINANDAN HWEALT/004311/ICI/05.01.2024 | D29: 8 | G29: =SUM(E29:F29) -> 0 | H29: 9600 | I29: =I28+G29 -> 111339 | J29: 45681 | K29: ICICI | L29: TRF/SHRI MURTINANDAN HWEALT/004311/ICI/05.01.2024 | M29: 4 | O29: 8640 | P29: =P28+N29 -> 6500 | Q29: =I29-P29 -> 104839
A30: 45682 | G30: =SUM(E30:F30) -> 0 | I30: =I29+G30 -> 111339 | J30: 45682 | K30: TDStoIT | M30: 10 | O30: 960 | P30: =P29+N30 -> 6500 | Q30: =I30-P30 -> 104839
A31: 45683 | B31: ICICI | C31: NFS/CASH WDL/402522024752/S1ACAG49/AGRA /25-01 | D31: 4 | F31: 10000 | G31: =SUM(E31:F31) -> 10000 | I31: =I30+G31 -> 121339 | J31: 45683 | P31: =P30+N31 -> 6500 | Q31: =I31-P31 -> 114839
A32: 45684 | G32: =SUM(E32:F32) -> 0 | I32: =I31+G32 -> 121339 | J32: 45684 | P32: =P31+N32 -> 6500 | Q32: =I32-P32 -> 114839
A33: 45685 | G33: =SUM(E33:F33) -> 0 | I33: =I32+G33 -> 121339 | J33: 45685 | P33: =P32+N33 -> 6500 | Q33: =I33-P33 -> 114839
A34: 45686 | G34: =SUM(E34:F34) -> 0 | I34: =I33+G34 -> 121339 | J34: 45686 | P34: =P33+N34 -> 6500 | Q34: =I34-P34 -> 114839
A35: 45687 | G35: =SUM(E35:F35) -> 0 | I35: =I34+G35 -> 121339 | J35: 45687 | P35: =P34+N35 -> 6500 | Q35: =I35-P35 -> 114839
A36: 45688 | G36: =SUM(E36:F36) -> 0 | I36: =I35+G36 -> 121339 | J36: 45688 | K36: Balance | L36: C/F | N36: =Q35 -> 114839 | P36: =P35+N36 -> 121339 | Q36: =I36-P36 -> 0
A37: 45688 | J37: 45688
H39: =SUM(H6:H36) -> 14748 | O39: =SUM(O6:O36) -> 14748

Sheet Feb
A2: CB2025-2026.xlsx | C2: Anurag-Professional | D2: Status: | E2: Individual | G2: CASHBOOK | I2: PAN: | J2: AFIPG7802B | L2: Asst.Yr. | N2: Month | O2: =CHOOSE(MONTH(A6),"Jan","Feb","Mar","Apr","May","Jun","Jul","Aug","Sep","Oct","Nov","Dec") -> Feb
A4: Date | B4: Reciept A/c | C4: Reciept Particulars | D4: L.F. No. | E4: VNH | F4: Cash | G4: Cash | H4: Chq. | I4: Total | J4: Date | K4: Payment A/c | L4: Payment Particulars | M4: L.F. No. | N4: Cash | O4: Chq. | P4: Total | Q4: Balance
A6: 45689 | B6: Balance | C6: B/F | F6: =Jan!N36 -> 114839 | G6: =Jan!N36 -> 114839 | I6: =I5+G6 -> 114839 | J6: 45689 | P6: =P5+N6 -> 0 | Q6: =I6-P6 -> 114839
A7: 45690 | G7: =SUM(E7:F7) -> 0 | I7: =I6+G7 -> 114839 | J7: 45690 | K7: Salary | L7: Neeraj | M7: 9 | N7: 3000 | P7: =P6+N7 -> 3000 | Q7: =I7-P7 -> 111839
A8: 45691 | G8: =SUM(E8:F8) -> 0 | I8: =I7+G8 -> 114839 | J8: 45691 | P8: =P7+N8 -> 3000 | Q8: =I8-P8 -> 111839
A9: 45692 | G9: =SUM(E9:F9) -> 0 | I9: =I8+G9 -> 114839 | J9: 45692 | P9: =P8+N9 -> 3000 | Q9: =I9-P9 -> 111839
A10: 45693 | B10: Patients | C10: UPI/avneshjain.agra/UPI/UNION BANK OF I/540232791818/ICI0f58808fdff34a76848506c81c218908 | G10: =SUM(E10:F10) -> 0 | H10: 300 | I10: =I9+G10 -> 114839 | J10: 45693 | K10: ICICI | L10: UPI/avneshjain.agra/UPI/UNION BANK OF I/540232791818/ICI0f58808fdff34a76848506c81c218908 | M10: 11 | O10: 300 | P10: =P9+N10 -> 3000 | Q10: =I10-P10 -> 111839
A11: 45694 | G11: =SUM(E11:F11) -> 0 | I11: =I10+G11 -> 114839 | J11: 45694 | P11: =P10+N11 -> 3000 | Q11: =I11-P11 -> 111839
A12: 45695 | G12: =SUM(E12:F12) -> 0 | I12: =I11+G12 -> 114839 | J12: 45695 | P12: =P11+N12 -> 3000 | Q12: =I12-P12 -> 111839
A13: 45696 | G13: =SUM(E13:F13) -> 0 | I13: =I12+G13 -> 114839 | J13: 45696 | P13: =P12+N13 -> 3000 | Q13: =I13-P13 -> 111839
A14: 45697 | G14: =SUM(E14:F14) -> 0 | I14: =I13+G14 -> 114839 | J14: 45697 | P14: =P13+N14 -> 3000 | Q14: =I14-P14 -> 111839
A15: 45698 | I15: =I14+G15 -> 114839 | J15: 45698 | P15: =P14+N15 -> 3000 | Q15: =I15-P15 -> 111839
A16: 45699 | G16: =SUM(E16:F16) -> 0 | I16: =I15+G16 -> 114839 | J16: 45699 | P16: =P15+N16 -> 3000 | Q16: =I16-P16 -> 111839
A17: 45700 | G17: =SUM(E17:F17) -> 0 | I17: =I16+G17 -> 114839 | J17: 45700 | P17: =P16+N17 -> 3000 | Q17: =I17-P17 -> 111839
A18: 45701 | B18: Patients | C18: TRF/SHRI MARUTINANDAN/005591/ICI/04.02.2025 | G18: =SUM(E18:F18) -> 0 | H18: =41130*1.1 -> 45243 | I18: =I17+G18 -> 114839 | J18: 45701 | K18: ICICI | L18: TRF/SHRI MARUTINANDAN/005591/ICI/04.02.2025 | O18: 41130 | P18: =P17+N18 -> 3000 | Q18: =I18-P18 -> 111839
A19: 45701 | G19: =SUM(E19:F19) -> 0 | I19: =I18+G19 -> 114839 | J19: 45701 | K19: TDStoIT | O19: 4113 | P19: =P18+N19 -> 3000 | Q19: =I19-P19 -> 111839
A20: 45703 | B20: ICICI | C20: ATM/S1CNQ071/CASH WDL/13-02-24 | D20: 4 | F20: 10000 | G20: =SUM(E20:F20) -> 10000 | I20: =I19+G20 -> 124839 | J20: 45703 | P20: =P19+N20 -> 3000 | Q20: =I20-P20 -> 121839
A21: 45704 | G21: =SUM(E21:F21) -> 0 | I21: =I20+G21 -> 124839 | J21: 45704 | P21: =P20+N21 -> 3000 | Q21: =I21-P21 -> 121839
A22: 45705 | G22: =SUM(E22:F22) -> 0 | I22: =I21+G22 -> 124839 | J22: 45705 | P22: =P21+N22 -> 3000 | Q22: =I22-P22 -> 121839
A23: 45706 | G23: =SUM(E23:F23) -> 0 | I23: =I22+G23 -> 124839 | J23: 45706 | P23: =P22+N23 -> 3000 | Q23: =I23-P23 -> 121839
A24: 45707 | G24: =SUM(E24:F24) -> 0 | I24: =I23+G24 -> 124839 | J24: 45707 | P24: =P23+N24 -> 3000 | Q24: =I24-P24 -> 121839
A25: 45708 | G25: =SUM(E25:F25) -> 0 | I25: =I24+G25 -> 124839 | J25: 45708 | P25: =P24+N25 -> 3000 | Q25: =I25-P25 -> 121839
A26: 45709 | G26: =SUM(E26:F26) -> 0 | I26: =I25+G26 -> 124839 | J26: 45709 | P26: =P25+N26 -> 3000 | Q26: =I26-P26 -> 121839
A27: 45710 | G27: =SUM(E27:F27) -> 0 | I27: =I26+G27 -> 124839 | J27: 45710 | P27: =P26+N27 -> 3000 | Q27: =I27-P27 -> 121839
A28: 45711 | G28: =SUM(E28:F28) -> 0 | I28: =I27+G28 -> 124839 | J28: 45711 | K28: Salary | L28: Gaurav | M28: 9 | N28: 3000 | P28: =P27+N28 -> 6000 | Q28: =I28-P28 -> 118839
A29: 45712 | G29: =SUM(E29:F29) -> 0 | I29: =I28+G29 -> 124839 | J29: 45712 | P29: =P28+N29 -> 6000 | Q29: =I29-P29 -> 118839
A30: 45713 | G30: =SUM(E30:F30) -> 0 | I30: =I29+G30 -> 124839 | J30: 45713 | P30: =P29+N30 -> 6000 | Q30: =I30-P30 -> 118839
A31: 45714 | G31: =SUM(E31:F31) -> 0 | I31: =I30+G31 -> 124839 | J31: 45714 | P31: =P30+N31 -> 6000 | Q31: =I31-P31 -> 118839
A32: 45715 | G32: =SUM(E32:F32) -> 0 | I32: =I31+G32 -> 124839 | J32: 45715 | P32: =P31+N32 -> 6000 | Q32: =I32-P32 -> 118839
A33: 45716 | G33: =SUM(E33:F33) -> 0 | I33: =I32+G33 -> 124839 | J33: 45716 | P33: =P32+N33 -> 6000 | Q33: =I33-P33 -> 118839
A34: 45716 | G34: =SUM(E34:F34) -> 0 | I34: =I33+G34 -> 124839 | J34: 45716 | P34: =P33+N34 -> 6000 | Q34: =I34-P34 -> 118839
A35: 45716 | G35: =SUM(E35:F35) -> 0 | I35: =I34+G35 -> 124839 | J35: 45716 | P35: =P34+N35 -> 6000 | Q35: =I35-P35 -> 118839
A36: 45716 | J36: 45716
A37: 45716 | G37: =SUM(E37:F37) -> 0 | I37: =I35+G37 -> 124839 | J37: 45716 | P37: =P35+N36 -> 6000 | Q37: =I37-P37 -> 118839
A38: 45716 | G38: =SUM(E38:F38) -> 0 | I38: =I37+G38 -> 124839 | J38: 45716 | P38: =P37+N38 -> 6000 | Q38: =I38-P38 -> 118839
A39: 45716 | G39: =SUM(E39:F39) -> 0 | I39: =I38+G39 -> 124839 | J39: 45716 | P39: =P38+N39 -> 6000 | Q39: =I39-P39 -> 118839
A40: 45716 | G40: =SUM(E40:F40) -> 0 | I40: =I39+G40 -> 124839 | J40: 45716 | P40: =P39+N40 -> 6000 | Q40: =I40-P40 -> 118839
A41: 45716 | G41: =SUM(E41:F41) -> 0 | I41: =I40+G41 -> 124839 | J41: 45716 | P41: =P40+N41 -> 6000 | Q41: =I41-P41 -> 118839
A42: 45716 | G42: =SUM(E42:F42) -> 0 | I42: =I41+G42 -> 124839 | J42: 45716 | P42: =P41+N42 -> 6000 | Q42: =I42-P42 -> 118839
A43: 45716 | G43: =SUM(E43:F43) -> 0 | I43: =I42+G43 -> 124839 | J43: 45716 | K43: Balance | L43: C/F | N43: =Q42 -> 118839 | P43: =P42+N43 -> 124839 | Q43: =I43-P43 -> 0
...

Sheet Mar
A2: CB2025-2026.xlsx | C2: Anurag-Professional | D2: Status: | E2: Individual | G2: CASHBOOK | I2: PAN: | J2: AFIPG7802B | L2: Asst.Yr. | N2: Month | O2: =CHOOSE(MONTH(A6),"Jan","Feb","Mar","Apr","May","Jun","Jul","Aug","Sep","Oct","Nov","Dec") -> Mar
A4: Date | B4: Reciept A/c | C4: Reciept Particulars | D4: L.F. No. | E4: VNH | F4: Cash | G4: Cash | H4: Chq. | I4: Total | J4: Date | K4: Payment A/c | L4: Payment Particulars | M4: L.F. No. | N4: Cash | O4: Chq. | P4: Total | Q4: Balance
A6: 45717 | B6: Balance | C6: B/F | F6: =Feb!N43 -> 118839 | G6: =Feb!N43 -> 118839 | I6: =I5+G6 -> 118839 | J6: 45717 | P6: =P5+N6 -> 0 | Q6: =I6-P6 -> 118839
A7: 45718 | G7: =SUM(E7:F7) -> 0 | I7: =I6+G7 -> 118839 | J7: 45718 | K7: Salary | L7: Neeraj | M7: 9 | N7: 3000 | P7: =P6+N7 -> 3000 | Q7: =I7-P7 -> 115839
A8: 45719 | G8: =SUM(E8:F8) -> 0 | I8: =I7+G8 -> 118839 | J8: 45719 | P8: =P7+N8 -> 3000 | Q8: =I8-P8 -> 115839
A9: 45720 | B9: Patients | C9: TRF/SHRI MARUTINANDAN/004572/ICI/25.02.2024 | D9: 8 | G9: =SUM(E9:F9) -> 0 | H9: 2700 | I9: =I8+G9 -> 118839 | J9: 45720 | K9: ICICI | L9: TRF/SHRI MARUTINANDAN/004572/ICI/25.02.2024 | M9: 4 | O9: 2430 | P9: =P8+N9 -> 3000 | Q9: =I9-P9 -> 115839
A10: 45721 | G10: =SUM(E10:F10) -> 0 | I10: =I9+G10 -> 118839 | J10: 45721 | K10: TDStoIT | M10: 10 | O10: 270 | P10: =P9+N10 -> 3000 | Q10: =I10-P10 -> 115839
A11: 45722 | G11: =SUM(E11:F11) -> 0 | I11: =I10+G11 -> 118839 | J11: 45722 | P11: =P10+N11 -> 3000 | Q11: =I11-P11 -> 115839
A12: 45723 | G12: =SUM(E12:F12) -> 0 | I12: =I11+G12 -> 118839 | J12: 45723 | P12: =P11+N12 -> 3000 | Q12: =I12-P12 -> 115839
A13: 45724 | G13: =SUM(E13:F13) -> 0 | I13: =I12+G13 -> 118839 | J13: 45724 | P13: =P12+N13 -> 3000 | Q13: =I13-P13 -> 115839
A14: 45725 | G14: =SUM(E14:F14) -> 0 | I14: =I13+G14 -> 118839 | J14: 45725 | K14: Veh. Exp. | L14: Petrol | M14: 11 | N14: 500 | P14: =P13+N14 -> 3500 | Q14: =I14-P14 -> 115339
A15: 45726 | G15: =SUM(E15:F15) -> 0 | I15: =I14+G15 -> 118839 | J15: 45726 | P15: =P14+N15 -> 3500 | Q15: =I15-P15 -> 115339
